<?xml version="1.0"?>
<robot name="differential_robot" xmlns:xacro="http://ros.org/wiki/xacro">
    <!-- Define robot constants in meters-->
    <xacro:property name="base_inner_width" value="0.281432"/><!-- Along x axis -->
    <xacro:property name="base_outer_width" value="0.5842"/><!-- Along x axis -->
    <xacro:property name="base_length" value="0.917575"/><!-- Along y axis -->
    <xacro:property name="base_height" value="0.509778"/><!-- Along z axis -->
    <xacro:property name="base_ground_height_zoffset" value="0.054356"/><!-- Along z axis -->

    <xacro:property name="wheel_radius" value="0.087757"/>
    <xacro:property name="wheel_width" value="0.0956564"/>
    <xacro:property name="wheel_to_chassis_gap" value="0.054864"/><!-- Along x axis -->
    <xacro:property name="wheel_ygap" value="0.540004"/><!-- Along y axis distance between axis of rotation-->
    <xacro:property name="wheel_xgap" value="0.39116"/>

    <xacro:property name="camera_z" value="0.38735"/><!-- Along z axis distance between bar and bottom of frame-->
    <xacro:property name="camera_y" value="0.136398"/><!-- From axel of the front wheel to the y value of the frame-->
    <xacro:property name="camera_y_from_center_of_robot" value="${camera_y + wheel_ygap/2}"/>


    <!-- Robot Base -->
    <link name="base_link">
        <visual>
            <origin xyz="0 0 0" rpy="0 0 0"/>
            <geometry>
                <box size="${base_inner_width} ${base_length} ${base_height}"/>
            </geometry>
        <material name="UIUCBlue">
            <color rgba=".19 .41 .75 1.0"/>
        </material>
        </visual>
    </link>

    <!-- Robot Footprint -->
    <link name="base_footprint"/>

    <joint name="base_joint" type="fixed">
        <parent link="base_link"/>
        <child link="base_footprint"/>
        <origin xyz="0.0 0.0 ${-(base_height / 2 + base_ground_height_zoffset)}" rpy="0 0 0"/>
    </joint>

    <!-- Wheels -->
    <xacro:macro name="wheel" params="name y_reflect">
        <link name="${name}_y_plus_link">
        <visual>
            <origin xyz="0 0 0" rpy="0 ${pi/2} 0"/>
            <geometry>
                <cylinder radius="${wheel_radius}" length="${wheel_width}"/>
            </geometry>
            <material name="Gray">
            <color rgba="0.5 0.5 0.5 1.0"/>
            </material>
        </visual>
        </link>

        <joint name="${name}_y_plus_joint" type="continuous">
            <parent link="base_link"/>
            <child link="${name}_y_plus_link"/>
            <origin xyz="${y_reflect*(base_inner_width/2 + wheel_to_chassis_gap)} ${wheel_ygap/2} ${-base_height / 2 - base_ground_height_zoffset + wheel_radius}" rpy="0 0 0"/>
            <axis xyz="1 0 0"/>
        </joint>

        <link name="${name}_y_minus_link">
            <visual>
                <origin xyz="0 0 0" rpy="0 ${pi/2} 0"/>
                <geometry>
                    <cylinder radius="${wheel_radius}" length="${wheel_width}"/>
                </geometry>
                <material name="Gray">
                <color rgba="0.5 0.5 0.5 1.0"/>
                </material>
            </visual>
            </link>

        <joint name="${name}_y_minus_joint" type="continuous">
            <parent link="base_link"/>
            <child link="${name}_y_minus_link"/>
            <origin xyz="${y_reflect*(base_inner_width/2 + wheel_to_chassis_gap)} ${-wheel_ygap/2} ${-base_height / 2 - base_ground_height_zoffset + wheel_radius}" rpy="0 0 0"/>
            <axis xyz="1 0 0"/>
        </joint>
    </xacro:macro>

    <xacro:wheel name="drivewhl_l" y_reflect="-1" />
    <xacro:wheel name="drivewhl_r" y_reflect="1" />

</robot>